<?xml version="1.0" encoding="utf-8"?>
<!-- This URDF was automatically created by SolidWorks to URDF Exporter! Originally created by Stephen Brawner (brawner@gmail.com) 
     Commit Version: 1.6.0-1-g15f4949  Build Version: 1.6.7594.29634
     For more information, please see http://wiki.ros.org/sw_urdf_exporter -->
<robot
  name="door_u">
  <link
    name="door_base">
    <inertial>
      <origin
        xyz="0.45 0.45 0.05"
        rpy="0 0 0" />
      <mass
        value="1000" />
      <inertia
        ixx="130.249"
        ixy="-7.2974E-17"
        ixz="2.1091"
        iyy="140.012"
        iyz="1.2485E-14"
        izz="110.701" />
    </inertial>
    <visual>
      <origin
        xyz="0 0 0"
        rpy="0 0 0" />
      <geometry>
        <mesh
          filename="package://door_u/meshes/door_base.STL" />
      </geometry>
      <material
        name="">
        <color
          rgba="0.79216 0.81961 0.93333 1" />
      </material>
    </visual>
    <collision>
      <origin
        xyz="0 0 0"
        rpy="0 0 0" />
      <geometry>
        <mesh
          filename="package://door_u/meshes/door_base.STL" />
      </geometry>
    </collision>
  </link>
  <link
    name="door">
    <inertial>
      <origin
        xyz="0.45 0 0.9"
        rpy="0 0 0" />
      <mass
        value="0.01" />
      <inertia
        ixx="0.001"
        ixy="-0.0076459"
        ixz="-0.0069729"
        iyy="0.001"
        iyz="-0.0019667"
        izz="0.001" />
    </inertial>
    <visual>
      <origin
        xyz="0 0 0"
        rpy="0 0 0" />
      <geometry>
        <mesh
          filename="package://door_u/meshes/door.STL" />
      </geometry>
      <material
        name="">
        <color
          rgba="0.1 0.9 0.1 1" />
      </material>
    </visual>
    <collision>
      <origin
        xyz="0 0 0"
        rpy="0 0 0" />
      <geometry>
        <mesh
          filename="package://door_u/meshes/door.STL" />
      </geometry>
    </collision>
  </link>
  <joint
    name="door_hinge_joint"
    type="revolute">
    <origin
      xyz="0.07 0.45 0.1"
      rpy="0 0 0" />
    <parent
      link="door_base" />
    <child
      link="door" />
    <axis
      xyz="0 0 1" />
    <limit
      lower="-100000"
      upper="100000"
      effort="100"
      velocity="1000" />
  </joint>
</robot>